2023-03-13 19:38:25,271 DEBUG    root            Loaded Command Group: ['gcloud', 'auth']
2023-03-13 19:38:25,272 DEBUG    root            Loaded Command Group: ['gcloud', 'auth', 'application_default']
2023-03-13 19:38:25,273 DEBUG    root            Loaded Command Group: ['gcloud', 'auth', 'application-default', 'print_access_token']
2023-03-13 19:38:25,274 DEBUG    root            Running [gcloud.auth.application-default.print-access-token] with arguments: [--quiet: "True", --verbosity: "warning"]
2023-03-13 19:38:25,274 DEBUG    google.auth.transport._http_client Making request: GET http://169.254.169.254
2023-03-13 19:38:25,275 WARNING  google.auth.compute_engine._metadata Compute Engine Metadata server unavailable on attempt 1 of 3. Reason: [Errno 64] Host is down
2023-03-13 19:38:25,275 DEBUG    google.auth.transport._http_client Making request: GET http://169.254.169.254
2023-03-13 19:38:25,275 WARNING  google.auth.compute_engine._metadata Compute Engine Metadata server unavailable on attempt 2 of 3. Reason: [Errno 64] Host is down
2023-03-13 19:38:25,275 DEBUG    google.auth.transport._http_client Making request: GET http://169.254.169.254
2023-03-13 19:38:25,275 WARNING  google.auth.compute_engine._metadata Compute Engine Metadata server unavailable on attempt 3 of 3. Reason: [Errno 64] Host is down
2023-03-13 19:38:25,275 DEBUG    root            Could not automatically determine credentials. Please set GOOGLE_APPLICATION_CREDENTIALS or explicitly create credentials and re-run the application. For more information, please see https://cloud.google.com/docs/authentication/getting-started
Traceback (most recent call last):
  File "/Users/auxia/Library/Application Support/cloud-code/installer/google-cloud-sdk/lib/surface/auth/application_default/print_access_token.py", line 106, in Run
    creds, _ = c_creds.GetGoogleAuthDefault().default(
  File "/Users/auxia/Library/Application Support/cloud-code/installer/google-cloud-sdk/lib/third_party/google/auth/_default.py", line 653, in default
    raise exceptions.DefaultCredentialsError(_HELP_MESSAGE)
google.auth.exceptions.DefaultCredentialsError: Could not automatically determine credentials. Please set GOOGLE_APPLICATION_CREDENTIALS or explicitly create credentials and re-run the application. For more information, please see https://cloud.google.com/docs/authentication/getting-started
2023-03-13 19:38:25,276 DEBUG    root            (gcloud.auth.application-default.print-access-token) Could not automatically determine credentials. Please set GOOGLE_APPLICATION_CREDENTIALS or explicitly create credentials and re-run the application. For more information, please see https://cloud.google.com/docs/authentication/getting-started
Traceback (most recent call last):
  File "/Users/auxia/Library/Application Support/cloud-code/installer/google-cloud-sdk/lib/surface/auth/application_default/print_access_token.py", line 106, in Run
    creds, _ = c_creds.GetGoogleAuthDefault().default(
  File "/Users/auxia/Library/Application Support/cloud-code/installer/google-cloud-sdk/lib/third_party/google/auth/_default.py", line 653, in default
    raise exceptions.DefaultCredentialsError(_HELP_MESSAGE)
google.auth.exceptions.DefaultCredentialsError: Could not automatically determine credentials. Please set GOOGLE_APPLICATION_CREDENTIALS or explicitly create credentials and re-run the application. For more information, please see https://cloud.google.com/docs/authentication/getting-started

During handling of the above exception, another exception occurred:

Traceback (most recent call last):
  File "/Users/auxia/Library/Application Support/cloud-code/installer/google-cloud-sdk/lib/googlecloudsdk/calliope/cli.py", line 987, in Execute
    resources = calliope_command.Run(cli=self, args=args)
  File "/Users/auxia/Library/Application Support/cloud-code/installer/google-cloud-sdk/lib/googlecloudsdk/calliope/backend.py", line 807, in Run
    resources = command_instance.Run(args)
  File "/Users/auxia/Library/Application Support/cloud-code/installer/google-cloud-sdk/lib/surface/auth/application_default/print_access_token.py", line 110, in Run
    raise c_exc.ToolException(six.text_type(e))
googlecloudsdk.calliope.exceptions.ToolException: Could not automatically determine credentials. Please set GOOGLE_APPLICATION_CREDENTIALS or explicitly create credentials and re-run the application. For more information, please see https://cloud.google.com/docs/authentication/getting-started
2023-03-13 19:38:25,276 ERROR    root            (gcloud.auth.application-default.print-access-token) Could not automatically determine credentials. Please set GOOGLE_APPLICATION_CREDENTIALS or explicitly create credentials and re-run the application. For more information, please see https://cloud.google.com/docs/authentication/getting-started
