2023-02-18 20:42:18,815 DEBUG    root            Loaded Command Group: ['gcloud', 'auth']
2023-02-18 20:42:18,816 DEBUG    root            Loaded Command Group: ['gcloud', 'version']
2023-02-18 20:42:18,817 DEBUG    root            Loaded Command Group: ['gcloud', 'auth', 'application_default']
2023-02-18 20:42:18,817 DEBUG    root            Running [gcloud.version] with arguments: [--format: "json"]
2023-02-18 20:42:18,818 DEBUG    root            Loaded Command Group: ['gcloud', 'auth', 'application-default', 'print_access_token']
2023-02-18 20:42:18,819 DEBUG    root            Running [gcloud.auth.application-default.print-access-token] with arguments: [--quiet: "True", --verbosity: "warning"]
2023-02-18 20:42:18,819 DEBUG    google.auth.transport._http_client Making request: GET http://169.254.169.254
2023-02-18 20:42:18,820 DEBUG    root            Chosen display Format:flattened[no-pad,separator=" "] json
2023-02-18 20:42:18,820 INFO     root            Display format: "flattened[no-pad,separator=" "] json"
2023-02-18 20:42:18,820 INFO     ___FILE_ONLY___ {
  "Google Cloud SDK": "418.0.0",
  "bq": "2.0.85",
  "core": "2023.02.13",
  "gcloud-crc32c": "1.0.0",
  "gsutil": "5.20"
}
2023-02-18 20:42:18,820 INFO     ___FILE_ONLY___ 

2023-02-18 20:42:21,821 WARNING  google.auth.compute_engine._metadata Compute Engine Metadata server unavailable on attempt 1 of 3. Reason: timed out
2023-02-18 20:42:21,821 DEBUG    google.auth.transport._http_client Making request: GET http://169.254.169.254
2023-02-18 20:42:24,822 WARNING  google.auth.compute_engine._metadata Compute Engine Metadata server unavailable on attempt 2 of 3. Reason: timed out
2023-02-18 20:42:24,823 DEBUG    google.auth.transport._http_client Making request: GET http://169.254.169.254
2023-02-18 20:42:24,823 WARNING  google.auth.compute_engine._metadata Compute Engine Metadata server unavailable on attempt 3 of 3. Reason: [Errno 64] Host is down
2023-02-18 20:42:24,823 DEBUG    root            Could not automatically determine credentials. Please set GOOGLE_APPLICATION_CREDENTIALS or explicitly create credentials and re-run the application. For more information, please see https://cloud.google.com/docs/authentication/getting-started
Traceback (most recent call last):
  File "/Users/auxia/Library/Application Support/cloud-code/installer/google-cloud-sdk/lib/surface/auth/application_default/print_access_token.py", line 106, in Run
    creds, _ = c_creds.GetGoogleAuthDefault().default(
  File "/Users/auxia/Library/Application Support/cloud-code/installer/google-cloud-sdk/lib/third_party/google/auth/_default.py", line 653, in default
    raise exceptions.DefaultCredentialsError(_HELP_MESSAGE)
google.auth.exceptions.DefaultCredentialsError: Could not automatically determine credentials. Please set GOOGLE_APPLICATION_CREDENTIALS or explicitly create credentials and re-run the application. For more information, please see https://cloud.google.com/docs/authentication/getting-started
2023-02-18 20:42:24,823 DEBUG    root            (gcloud.auth.application-default.print-access-token) Could not automatically determine credentials. Please set GOOGLE_APPLICATION_CREDENTIALS or explicitly create credentials and re-run the application. For more information, please see https://cloud.google.com/docs/authentication/getting-started
Traceback (most recent call last):
  File "/Users/auxia/Library/Application Support/cloud-code/installer/google-cloud-sdk/lib/surface/auth/application_default/print_access_token.py", line 106, in Run
    creds, _ = c_creds.GetGoogleAuthDefault().default(
  File "/Users/auxia/Library/Application Support/cloud-code/installer/google-cloud-sdk/lib/third_party/google/auth/_default.py", line 653, in default
    raise exceptions.DefaultCredentialsError(_HELP_MESSAGE)
google.auth.exceptions.DefaultCredentialsError: Could not automatically determine credentials. Please set GOOGLE_APPLICATION_CREDENTIALS or explicitly create credentials and re-run the application. For more information, please see https://cloud.google.com/docs/authentication/getting-started

During handling of the above exception, another exception occurred:

Traceback (most recent call last):
  File "/Users/auxia/Library/Application Support/cloud-code/installer/google-cloud-sdk/lib/googlecloudsdk/calliope/cli.py", line 987, in Execute
    resources = calliope_command.Run(cli=self, args=args)
  File "/Users/auxia/Library/Application Support/cloud-code/installer/google-cloud-sdk/lib/googlecloudsdk/calliope/backend.py", line 807, in Run
    resources = command_instance.Run(args)
  File "/Users/auxia/Library/Application Support/cloud-code/installer/google-cloud-sdk/lib/surface/auth/application_default/print_access_token.py", line 110, in Run
    raise c_exc.ToolException(six.text_type(e))
googlecloudsdk.calliope.exceptions.ToolException: Could not automatically determine credentials. Please set GOOGLE_APPLICATION_CREDENTIALS or explicitly create credentials and re-run the application. For more information, please see https://cloud.google.com/docs/authentication/getting-started
2023-02-18 20:42:24,824 ERROR    root            (gcloud.auth.application-default.print-access-token) Could not automatically determine credentials. Please set GOOGLE_APPLICATION_CREDENTIALS or explicitly create credentials and re-run the application. For more information, please see https://cloud.google.com/docs/authentication/getting-started
